<?xml version="1.0" ?>
<!-- =================================================================================== -->
<!-- |    This document was autogenerated by xacro from gp400.xacro                    | -->
<!-- |    EDITING THIS FILE BY HAND IS NOT RECOMMENDED                                 | -->
<!-- =================================================================================== -->
<robot name="motoman_gp400">
  <!-- Properties -->
  <material name="Yaskawa_blue">
    <color rgba="0.12941 0.14902 0.74902 1"/>
  </material>
  <material name="Collision_yellow">
    <color rgba="1.0 1.0 0.0 1"/>
  </material>
  <material name="Component_grey">
    <color rgba="0.2 0.2 0.2 1"/>
  </material>
  <!-- link list -->
  <link name="base_link">
    <visual>
      <geometry>
        <mesh filename="package://motoman_gp400_support/meshes/visual/GP400_BASE_AXIS.stl"/>
      </geometry>
      <material name="Yaskawa_blue"/>
    </visual>
    <collision>
      <geometry>
        <mesh filename="package://motoman_gp400_support/meshes/visual/GP400_BASE_AXIS.stl"/>
      </geometry>
      <material name="Collision_yellow"/>
    </collision>
  </link>
  <link name="link_1">
    <visual>
      <geometry>
        <mesh filename="package://motoman_gp400_support/meshes/visual/GP400_S_AXIS.stl"/>
      </geometry>
      <material name="Yaskawa_blue"/>
    </visual>
    <collision>
      <geometry>
        <mesh filename="package://motoman_gp400_support/meshes/visual/GP400_S_AXIS.stl"/>
      </geometry>
      <material name="Collision_yellow"/>
    </collision>
  </link>
  <link name="link_2">
    <visual>
      <geometry>
        <mesh filename="package://motoman_gp400_support/meshes/visual/GP400_L_AXIS.stl"/>
      </geometry>
      <material name="Yaskawa_blue"/>
    </visual>
    <collision>
      <geometry>
        <mesh filename="package://motoman_gp400_support/meshes/collision/GP400_L_AXIS.stl"/>
      </geometry>
      <material name="Collision_yellow"/>
    </collision>
  </link>
  <link name="link_3">
    <visual>
      <geometry>
        <mesh filename="package://motoman_gp400_support/meshes/visual/GP400_U_AXIS.stl"/>
      </geometry>
      <material name="Yaskawa_blue"/>
    </visual>
    <collision>
      <geometry>
        <mesh filename="package://motoman_gp400_support/meshes/collision/GP400_U_AXIS.stl"/>
      </geometry>
      <material name="Collision_yellow"/>
    </collision>
  </link>
  <link name="link_4">
    <visual>
      <geometry>
        <mesh filename="package://motoman_gp400_support/meshes/visual/GP400_R_AXIS.stl"/>
      </geometry>
      <material name="Yaskawa_blue"/>
    </visual>
    <collision>
      <geometry>
        <mesh filename="package://motoman_gp400_support/meshes/collision/GP400_R_AXIS.stl"/>
      </geometry>
      <material name="Collision_yellow"/>
    </collision>
  </link>
  <link name="link_5">
    <visual>
      <geometry>
        <mesh filename="package://motoman_gp400_support/meshes/visual/GP400_B_AXIS.stl"/>
      </geometry>
      <material name="Yaskawa_blue"/>
    </visual>
    <collision>
      <geometry>
        <mesh filename="package://motoman_gp400_support/meshes/collision/GP400_B_AXIS.stl"/>
      </geometry>
      <material name="Collision_yellow"/>
    </collision>
  </link>
  <link name="link_6">
    <visual>
      <geometry>
        <mesh filename="package://motoman_gp400_support/meshes/visual/GP400_T_AXIS.stl"/>
      </geometry>
      <!-- <material name="${prefix}Yaskawa_blue"/> -->
      <material name="Component_grey"/>
    </visual>
    <collision>
      <geometry>
        <mesh filename="package://motoman_gp400_support/meshes/collision/GP400_T_AXIS.stl"/>
      </geometry>
      <material name="Collision_yellow"/>
    </collision>
  </link>
  <!-- Balancer A parallell to Link L -->
  <link name="balancer_A">
    <visual>
      <geometry>
        <!-- <mesh filename="package://motoman_gp400_support/meshes/visual/GP400_LINK_A_AXIS (Origin in upper joint).stl"/> -->
        <mesh filename="package://motoman_gp400_support/meshes/visual/GP400_LINK_A_AXIS.stl"/>
      </geometry>
      <material name="Yaskawa_blue"/>
    </visual>
    <collision>
      <geometry>
        <!-- <mesh filename="package://motoman_gp400_support/meshes/collision/GP400_LINK_A_AXIS (Origin in upper joint).stl"/> -->
        <mesh filename="package://motoman_gp400_support/meshes/collision/GP400_LINK_A_AXIS.stl"/>
      </geometry>
      <material name="Collision_yellow"/>
    </collision>
  </link>
  <!-- Balancer B parallell to Link U -->
  <link name="balancer_B">
    <visual>
      <geometry>
        <mesh filename="package://motoman_gp400_support/meshes/visual/GP400_LINK_B_AXIS.stl"/>
      </geometry>
      <material name="Yaskawa_blue"/>
    </visual>
    <collision>
      <geometry>
        <mesh filename="package://motoman_gp400_support/meshes/visual/GP400_LINK_B_AXIS.stl"/>
      </geometry>
      <material name="Collision_yellow"/>
    </collision>
  </link>
  <!-- Cylinder Box -->
  <link name="cylinderbox">
    <visual>
      <geometry>
        <mesh filename="package://motoman_gp400_support/meshes/visual/GP400_BALANCER_1_AXIS.stl"/>
      </geometry>
      <!-- <material name="${prefix}Yaskawa_blue"/> -->
      <material name="Component_grey"/>
    </visual>
    <collision>
      <geometry>
        <mesh filename="package://motoman_gp400_support/meshes/collision/GP400_BALANCER_1_AXIS.stl"/>
      </geometry>
      <material name="Collision_yellow"/>
    </collision>
  </link>
  <link name="tool0"/>
  <link name="fakelink"/>
  <!-- End of Link List -->
  <!-- Joint List -->
  <!-- S-Axis -->
  <joint name="joint_1" type="revolute">
    <parent link="base_link"/>
    <child link="link_1"/>
    <origin rpy="0 0 0" xyz="0.000 0.000 0.1445"/>
    <axis xyz="0 0 1"/>
    <limit effort="0" lower="-3.141592653589793" upper="3.141592653589793" velocity="1.78"/>
  </joint>
  <!-- L-Axis -->
  <joint name="joint_2" type="revolute">
    <parent link="link_1"/>
    <child link="link_2"/>
    <origin rpy="0 0 0" xyz="0.400 0.000 0.7555"/>
    <axis xyz="0 1 0"/>
    <limit effort="0" lower="-0.9599310885968813" upper="1.064650843716541" velocity="1.69"/>
  </joint>
  <!-- U-Axis -->
  <joint name="joint_3" type="revolute">
    <parent link="link_2"/>
    <child link="link_3"/>
    <origin rpy="0 0 0" xyz="0.000 0.000 1.050"/>
    <axis xyz="0 -1 0"/>
    <!-- <limit lower="${radians(-18)}" upper="${radians(113)}" velocity="1.69" effort="0"/> -->
    <!-- <limit lower="${radians(-52)}" upper="${radians(61)}" velocity="1.69" effort="0"/> -->
    <limit effort="0" lower="-1.064650843716541" upper="0.29670597283903605" velocity="1.69"/>
    <!-- Lower = -113 + 61 -->
    <!-- Upper = 61-->
  </joint>
  <!-- R-Axis -->
  <joint name="joint_4" type="revolute">
    <parent link="link_3"/>
    <child link="link_4"/>
    <origin rpy="0 0 0" xyz="1.31772 0.000 0.250"/>
    <axis xyz="-1 0 0"/>
    <!-- <limit lower="${radians(-360)}" upper="${radians(360)}" velocity="1.40" effort="0"/> -->
    <limit effort="0" lower="-2.0943951023931953" upper="2.0943951023931953" velocity="1.40"/>
  </joint>
  <!-- B-Axis -->
  <joint name="joint_5" type="revolute">
    <parent link="link_4"/>
    <child link="link_5"/>
    <origin rpy="3.141592653589793 0 0" xyz="0.28728 0.000 0.000"/>
    <axis xyz="0 1 0"/>
    <limit effort="0" lower="-2.007128639793479" upper="2.007128639793479" velocity="1.40"/>
  </joint>
  <!-- T-Axis -->
  <joint name="joint_6" type="revolute">
    <parent link="link_5"/>
    <child link="link_6"/>
    <origin rpy="0 0 0" xyz="0.266 0.000 0.000"/>
    <axis xyz="-1 0 0"/>
    <!-- <limit lower="${radians(-360)}" upper="${radians(360)}" velocity="3.00" effort="0"/> -->
    <limit effort="0" lower="-2.0943951023931953" upper="2.0943951023931953" velocity="3.00"/>
  </joint>
  <!-- EOAT -->
  <joint name="joint_6-tool0" type="fixed">
    <origin rpy="0 1.5707963267948966 0" xyz="0.034 0.000 0.000"/>
    <parent link="link_6"/>
    <child link="tool0"/>
  </joint>
  <!-- Fakelinke for Balancer B -->
  <joint name="link1_adjustment" type="revolute">
    <origin rpy="0 0 0" xyz="0.400 0.000 0.7555"/>
    <parent link="link_1"/>
    <child link="fakelink"/>
    <axis xyz="0 1 0"/>
    <mimic joint="joint_2" multiplier="1"/>
    <limit effort="0" lower="-1.9722220547535925" upper="1.064650843716541" velocity="1.69"/>
  </joint>
  <!-- Balancer B parallell to Link U -->
  <joint name="balancer_B" type="revolute">
    <parent link="fakelink"/>
    <child link="balancer_B"/>
    <!-- <origin xyz="0.000 -0.104 0.000" rpy="0 0 0" /> -->
    <origin rpy="0 0 0" xyz="0.000 -0.100 0.000"/>
    <axis xyz="0 -1 0"/>
    <mimic joint="joint_3" multiplier="1.0"/>
    <limit effort="0" lower="-1.9722220547535925" upper="1.064650843716541" velocity="1.69"/>
  </joint>
  <!-- Balancer A parallell to Link L -->
  <joint name="balancer_A" type="revolute">
    <parent link="balancer_B"/>
    <child link="balancer_A"/>
    <origin rpy="0 0 0" xyz="-0.500 0.000 0.000"/>
    <axis xyz="0 1 0"/>
    <mimic joint="joint_3" multiplier="1.0"/>
    <limit effort="0" lower="-0.9599310885968813" upper="1.064650843716541" velocity="1.69"/>
  </joint>
  <!-- Balancer A parallell to Link L -->
  <!-- <joint name="${prefix}balancer_A" type="revolute">
            <parent link="${prefix}link_3"/>
            <child link="${prefix}balancer_A"/>
            <origin xyz="-0.500 -0.110 0.000" rpy="0 0 0" />
            <axis xyz="0 1 0" />
            <mimic joint="${prefix}joint_3" multiplier="1.0"/>
            <limit lower="${radians(-55)}" upper="${radians(61)}" velocity="1.69" effort="0"/>
        </joint> -->
  <!-- Balancer B parallell to Link U -->
  <!-- <joint name="${prefix}balancer_B" type="revolute">
            <parent link="${prefix}link_2"/>
            <child link="${prefix}balancer_B"/>
            <origin xyz="0.000 -0.104 0.000" rpy="0 0 0" />
            <axis xyz="0 -1 0" />
            <mimic joint="${prefix}joint_3" multiplier="1.0"/>
            <limit lower="${radians(-113)}" upper="${radians(61)}" velocity="1.69" effort="0"/>
        </joint> -->
  <!-- Cylinder Box -->
  <joint name="cylinderbox" type="revolute">
    <parent link="link_1"/>
    <child link="cylinderbox"/>
    <origin rpy="0 -0.17453292519943295 0" xyz="-0.191 0.059 0.651"/>
    <axis xyz="0 -1 0"/>
    <mimic joint="joint_2" multiplier="0.35"/>
    <limit effort="0" lower="-0.9599310885968813" upper="1.064650843716541" velocity="1.69"/>
  </joint>
  <!-- End of joint List -->
</robot>
