<?xml version="1.0" ?>
<!-- =================================================================================== -->
<!-- |    This document was autogenerated by xacro from gp400.xacro                    | -->
<!-- |    EDITING THIS FILE BY HAND IS NOT RECOMMENDED                                 | -->
<!-- =================================================================================== -->
<robot name="motoman_gp400" xmlns:xacro="http://ros.org/wiki/xacro">
  <!-- Properties -->
  <material name="Yaskawa_blue">
    <color rgba="0.12941 0.14902 0.74902 1"/>
  </material>
  <material name="NOV_red">
    <color rgba="0.8 0.1412 0.1725 1"/>
  </material>
  <material name="Collision_yellow">
    <color rgba="1.0 1.0 0.0 1"/>
  </material>
  <material name="Component_grey">
    <color rgba="0.2 0.2 0.2 1"/>
  </material>
  <!-- link list -->
  <link name="base_link">
    <visual>
      <geometry>
        <mesh filename="package://motoman_gp400/meshes/visual/GP400_BASE_AXIS.stl"/>
      </geometry>
      <material name="NOV_red"/>
    </visual>
    <collision>
      <geometry>
        <mesh filename="package://motoman_gp400/meshes/visual/GP400_BASE_AXIS.stl"/>
      </geometry>
      <material name="Collision_yellow"/>
    </collision>
  </link>
  <link name="link_1">
    <visual>
      <geometry>
        <mesh filename="package://motoman_gp400/meshes/visual/GP400_S_AXIS.stl"/>
      </geometry>
      <material name="NOV_red"/>
    </visual>
    <collision>
      <geometry>
        <mesh filename="package://motoman_gp400/meshes/visual/GP400_S_AXIS.stl"/>
      </geometry>
      <material name="Collision_yellow"/>
    </collision>
  </link>
  <link name="link_2">
    <visual>
      <geometry>
        <mesh filename="package://motoman_gp400/meshes/visual/GP400_L_AXIS.stl"/>
      </geometry>
      <material name="NOV_red"/>
    </visual>
    <collision>
      <geometry>
        <mesh filename="package://motoman_gp400/meshes/collision/GP400_L_AXIS.stl"/>
      </geometry>
      <material name="Collision_yellow"/>
    </collision>
  </link>
  <link name="link_3">
    <visual>
      <geometry>
        <mesh filename="package://motoman_gp400/meshes/visual/GP400_U_AXIS.stl"/>
      </geometry>
      <material name="NOV_red"/>
    </visual>
    <collision>
      <geometry>
        <mesh filename="package://motoman_gp400/meshes/collision/GP400_U_AXIS.stl"/>
      </geometry>
      <material name="Collision_yellow"/>
    </collision>
  </link>
  <link name="link_4">
    <visual>
      <geometry>
        <mesh filename="package://motoman_gp400/meshes/visual/GP400_R_AXIS.stl"/>
      </geometry>
      <material name="NOV_red"/>
    </visual>
    <collision>
      <geometry>
        <mesh filename="package://motoman_gp400/meshes/collision/GP400_R_AXIS.stl"/>
      </geometry>
      <material name="Collision_yellow"/>
    </collision>
  </link>
  <link name="link_5">
    <visual>
      <geometry>
        <mesh filename="package://motoman_gp400/meshes/visual/GP400_B_AXIS.stl"/>
      </geometry>
      <material name="NOV_red"/>
    </visual>
    <collision>
      <geometry>
        <mesh filename="package://motoman_gp400/meshes/collision/GP400_B_AXIS.stl"/>
      </geometry>
      <material name="Collision_yellow"/>
    </collision>
  </link>
  <link name="link_6">
    <visual>
      <geometry>
        <mesh filename="package://motoman_gp400/meshes/visual/GP400_T_AXIS.stl"/>
      </geometry>
      <!-- <material name="${prefix}NOV_red"/> -->
      <material name="Component_grey"/>
    </visual>
    <collision>
      <geometry>
        <mesh filename="package://motoman_gp400/meshes/collision/GP400_T_AXIS.stl"/>
      </geometry>
      <material name="Collision_yellow"/>
    </collision>
  </link>
  <!-- Balancer A parallell to Link L -->
  <link name="balancer_A">
    <visual>
      <geometry>
        <mesh filename="package://motoman_gp400/meshes/visual/GP400_LINK_A_AXIS (Origin in upper joint).stl"/>
        <!-- <mesh filename="package://motoman_gp400/meshes/visual/GP400_LINK_A_AXIS.stl"/> -->
      </geometry>
      <material name="NOV_red"/>
    </visual>
    <collision>
      <geometry>
        <mesh filename="package://motoman_gp400/meshes/collision/GP400_LINK_A_AXIS (Origin in upper joint).stl"/>
        <!-- <mesh filename="package://motoman_gp400/meshes/collision/GP400_LINK_A_AXIS.stl"/> -->
      </geometry>
      <material name="Collision_yellow"/>
    </collision>
  </link>
  <!-- Balancer B parallell to Link U -->
  <link name="balancer_B">
    <visual>
      <geometry>
        <mesh filename="package://motoman_gp400/meshes/visual/GP400_LINK_B_AXIS.stl"/>
      </geometry>
      <material name="NOV_red"/>
    </visual>
    <collision>
      <geometry>
        <mesh filename="package://motoman_gp400/meshes/visual/GP400_LINK_B_AXIS.stl"/>
      </geometry>
      <material name="Collision_yellow"/>
    </collision>
  </link>
  <!-- Cylinder Box -->
  <link name="cylinderbox">
    <visual>
      <geometry>
        <mesh filename="package://motoman_gp400/meshes/visual/GP400_BALANCER_1_AXIS.stl"/>
      </geometry>
      <!-- <material name="${prefix}NOV_red"/> -->
      <material name="Component_grey"/>
    </visual>
    <collision>
      <geometry>
        <mesh filename="package://motoman_gp400/meshes/collision/GP400_BALANCER_1_AXIS.stl"/>
      </geometry>
      <material name="Collision_yellow"/>
    </collision>
  </link>
  <link name="tool0"/>
  <link name="fakelinkA"/>
  <link name="fakelinkJ3"/>
  <!-- End of Link List -->
  <!-- Joint List -->
  <!-- S-Axis -->
  <joint name="joint_1" type="revolute">
    <parent link="base_link"/>
    <child link="link_1"/>
    <origin rpy="0 0 0" xyz="0.000 0.000 0.1445"/>
    <axis xyz="0 0 1"/>
    <limit effort="0" lower="-3.14159265359" upper="3.14159265359" velocity="1.78"/>
  </joint>
  <!-- L-Axis -->
  <joint name="joint_2" type="revolute">
    <parent link="link_1"/>
    <child link="link_2"/>
    <origin rpy="0 0 0" xyz="0.400 0.000 0.7555"/>
    <axis xyz="0 1 0"/>
    <limit effort="0" lower="-0.959931088597" upper="1.06465084372" velocity="1.69"/>
  </joint>
  <!-- U-Axis -->
  <joint name="fakelinkJ3_to_joint_2" type="revolute">
    <parent link="link_2"/>
    <child link="fakelinkJ3"/>
    <origin rpy="0 0 0" xyz="0.000 0.000 1.050"/>
    <axis xyz="0 1 0"/>
    <mimic joint="joint_2" multiplier="-1" offset="0.0"/>
    <limit effort="0" lower="-3.14159265359" upper="3.14159265359" velocity="1.69"/>
  </joint>
  <!-- U-Axis -->
  <joint name="joint_3" type="revolute">
    <parent link="fakelinkJ3"/>
    <child link="link_3"/>
    <origin rpy="0 0 0" xyz="0.000 0.000 0.000"/>
    <axis xyz="0 -1 0"/>
    <limit effort="0" lower="-0.907571211037" upper="1.06465084372" velocity="1.69"/>
  </joint>
  <!-- R-Axis -->
  <joint name="joint_4" type="revolute">
    <parent link="link_3"/>
    <child link="link_4"/>
    <origin rpy="0 0 0" xyz="1.31772 0.000 0.250"/>
    <axis xyz="-1 0 0"/>
    <limit effort="0" lower="-6.28318530718" upper="6.28318530718" velocity="1.40"/>
  </joint>
  <!-- B-Axis -->
  <joint name="joint_5" type="revolute">
    <parent link="link_4"/>
    <child link="link_5"/>
    <origin rpy="3.14159265359 0 0" xyz="0.28728 0.000 0.000"/>
    <axis xyz="0 1 0"/>
    <limit effort="0" lower="-2.00712863979" upper="2.00712863979" velocity="1.40"/>
  </joint>
  <!-- T-Axis -->
  <joint name="joint_6" type="revolute">
    <parent link="link_5"/>
    <child link="link_6"/>
    <origin rpy="0 0 0" xyz="0.266 0.000 0.000"/>
    <axis xyz="-1 0 0"/>
    <limit effort="0" lower="-6.28318530718" upper="6.28318530718" velocity="3.00"/>
  </joint>
  <!-- EOAT -->
  <joint name="joint_6-tool0" type="fixed">
    <origin rpy="0 1.57079632679 0" xyz="0.034 0.000 0.000"/>
    <parent link="link_6"/>
    <child link="tool0"/>
  </joint>
  <!-- Balancer B parallell to Link U -->
  <joint name="balancer_B" type="revolute">
    <parent link="link_1"/>
    <child link="balancer_B"/>
    <origin rpy="0 0 0" xyz="0.400 -0.100 0.7555"/>
    <axis xyz="0 -1 0"/>
    <mimic joint="joint_3" multiplier="1.0"/>
    <!-- <limit lower="${radians(-113)}" upper="${radians(61)}" velocity="1.69" effort="0"/> -->
    <limit effort="0" lower="-3.14159265359" upper="3.14159265359" velocity="1.69"/>
  </joint>
  <!-- Fakelinke for Balancer A -->
  <joint name="fakelinkA_to_BalancerA" type="revolute">
    <parent link="link_3"/>
    <child link="fakelinkA"/>
    <origin rpy="0 0 0" xyz="-0.500 -0.110 0.000"/>
    <axis xyz="0 1 0"/>
    <mimic joint="joint_3" multiplier="1" offset="0.0"/>
    <limit effort="0" lower="-3.14159265359" upper="3.14159265359" velocity="1.69"/>
  </joint>
  <!-- Fakelinke for Balancer A -->
  <joint name="fakelinkA_to_BalancerA" type="revolute">
    <parent link="link_3"/>
    <child link="fakelinkA"/>
    <origin rpy="0 0 0" xyz="-0.500 -0.110 0.000"/>
    <axis xyz="0 1 0"/>
    <mimic joint="joint_3" multiplier="1" offset="0.0"/>
    <limit effort="0" lower="-3.14159265359" upper="3.14159265359" velocity="1.69"/>
  </joint>
  <!-- Balancer A parallell to Link L -->
  <joint name="balancer_A" type="revolute">
    <parent link="fakelinkA"/>
    <child link="balancer_A"/>
    <origin rpy="0 0 0" xyz="0.000 0.000 0.000"/>
    <axis xyz="0 1 0"/>
    <mimic joint="joint_2" multiplier="1.0"/>
    <limit effort="0" lower="-0.959931088597" upper="1.06465084372" velocity="1.69"/>
  </joint>
  <!-- Cylinder Box -->
  <joint name="cylinderbox" type="revolute">
    <parent link="link_1"/>
    <child link="cylinderbox"/>
    <origin rpy="0 -0.174532925199 0" xyz="-0.191 0.059 0.651"/>
    <axis xyz="0 -1 0"/>
    <mimic joint="joint_2" multiplier="0.35"/>
    <limit effort="0" lower="-0.959931088597" upper="1.06465084372" velocity="1.69"/>
  </joint>
  <!-- End of joint List -->
</robot>
